Traceback (most recent call last):
  File "/usr/local/bin/pyro4-ns", line 11, in <module>
    sys.exit(main())
  File "/usr/local/lib/python2.7/site-packages/Pyro4/naming.py", line 555, in main
    hmac=options.key)
  File "/usr/local/lib/python2.7/site-packages/Pyro4/naming.py", line 463, in startNSloop
    daemon = NameServerDaemon(host, port, unixsocket, nathost=nathost, natport=natport, storage=storage)
  File "/usr/local/lib/python2.7/site-packages/Pyro4/naming.py", line 267, in __init__
    super(NameServerDaemon, self).__init__(host, port, unixsocket, nathost=nathost, natport=natport)
  File "/usr/local/lib/python2.7/site-packages/Pyro4/core.py", line 1088, in __init__
    self.transportServer.init(self, host, port, unixsocket)
  File "/usr/local/lib/python2.7/site-packages/Pyro4/socketserver/threadpoolserver.py", line 129, in init
    sslContext=sslContext)
  File "/usr/local/lib/python2.7/site-packages/Pyro4/socketutil.py", line 300, in createSocket
    sock.bind(bind)
  File "/usr/local/Cellar/python/2.7.11/Frameworks/Python.framework/Versions/2.7/lib/python2.7/socket.py", line 228, in meth
    return getattr(self._sock,name)(*args)
socket.error: [Errno 48] Address already in use
Traceback (most recent call last):
  File "/usr/local/bin/pyro4-ns", line 11, in <module>
    sys.exit(main())
  File "/usr/local/lib/python2.7/site-packages/Pyro4/naming.py", line 555, in main
    hmac=options.key)
  File "/usr/local/lib/python2.7/site-packages/Pyro4/naming.py", line 463, in startNSloop
    daemon = NameServerDaemon(host, port, unixsocket, nathost=nathost, natport=natport, storage=storage)
  File "/usr/local/lib/python2.7/site-packages/Pyro4/naming.py", line 267, in __init__
    super(NameServerDaemon, self).__init__(host, port, unixsocket, nathost=nathost, natport=natport)
  File "/usr/local/lib/python2.7/site-packages/Pyro4/core.py", line 1088, in __init__
    self.transportServer.init(self, host, port, unixsocket)
  File "/usr/local/lib/python2.7/site-packages/Pyro4/socketserver/threadpoolserver.py", line 129, in init
    sslContext=sslContext)
  File "/usr/local/lib/python2.7/site-packages/Pyro4/socketutil.py", line 300, in createSocket
    sock.bind(bind)
  File "/usr/local/Cellar/python/2.7.11/Frameworks/Python.framework/Versions/2.7/lib/python2.7/socket.py", line 228, in meth
    return getattr(self._sock,name)(*args)
socket.error: [Errno 48] Address already in use
